<?xml version="1.0" encoding="utf-8"?>
<!-- This URDF was automatically created by SolidWorks to URDF Exporter! Originally created by Stephen Brawner (brawner@gmail.com) 
     Commit Version: 1.6.0-4-g7f85cfe  Build Version: 1.6.7995.38578
     For more information, please see http://wiki.ros.org/sw_urdf_exporter -->
<robot
  name="Draw_armV4">
  <link
    name="Plate">
    <inertial>
      <origin
        xyz="1.1565E-19 0.005 3.6397E-17"
        rpy="0 0 0" />
      <mass
        value="0.08" />
      <inertia
        ixx="6.7333E-05"
        ixy="8.8966E-38"
        ixz="2.5235E-21"
        iyy="0.00010933"
        iyz="6.9592E-23"
        izz="4.3333E-05" />
    </inertial>
    <visual>
      <origin
        xyz="0 0 0"
        rpy="0 0 0" />
      <geometry>
        <mesh
          filename="package://Draw_armV4/meshes/Plate.STL" />
      </geometry>
      <material
        name="">
        <color
          rgba="0.79216 0.81961 0.93333 1" />
      </material>
    </visual>
    <collision>
      <origin
        xyz="0 0 0"
        rpy="0 0 0" />
      <geometry>
        <mesh
          filename="Plate.STL" />
      </geometry>
    </collision>
  </link>
  <link
    name="body1">
    <inertial>
      <origin
        xyz="-1.6336E-18 0.07008 7.331E-19"
        rpy="0 0 0" />
      <mass
        value="0.36914" />
      <inertia
        ixx="0.001159"
        ixy="-2.9387E-36"
        ixz="-2.0154E-37"
        iyy="0.00014985"
        iyz="1.9432E-20"
        izz="0.001159" />
    </inertial>
    <visual>
      <origin
        xyz="0 0 0"
        rpy="0 0 0" />
      <geometry>
        <mesh
          filename="package://Draw_armV4/meshes/body1.STL" />
      </geometry>
      <material
        name="">
        <color
          rgba="0.79216 0.81961 0.93333 1" />
      </material>
    </visual>
    <collision>
      <origin
        xyz="0 0 0"
        rpy="0 0 0" />
      <geometry>
        <mesh
          filename="package://Draw_armV4/meshes/body1.STL" />
      </geometry>
    </collision>
  </link>
  <joint
    name="jnt1"
    type="revolute">
    <origin
      xyz="0 0 0.01"
      rpy="1.5708 0 0" />
    <parent
      link="Plate" />
    <child
      link="body1" />
    <axis
      xyz="0 1 0" />
    <limit
      lower="-3.1416"
      upper="3.1416"
      effort="0"
      velocity="0" />
  </joint>
  <link
    name="body2">
    <inertial>
      <origin
        xyz="0.070782 3.024E-08 -5.5816E-08"
        rpy="0 0 0" />
      <mass
        value="0.26813" />
      <inertia
        ixx="6.19E-05"
        ixy="1.6236E-10"
        ixz="4.6572E-10"
        iyy="0.0012669"
        iyz="-2.9358E-10"
        izz="0.001262" />
    </inertial>
    <visual>
      <origin
        xyz="0 0 0"
        rpy="0 0 0" />
      <geometry>
        <mesh
          filename="package://Draw_armV4/meshes/body2.STL" />
      </geometry>
      <material
        name="">
        <color
          rgba="0.79216 0.81961 0.93333 1" />
      </material>
    </visual>
    <collision>
      <origin
        xyz="0 0 0"
        rpy="0 0 0" />
      <geometry>
        <mesh
          filename="package://Draw_armV4/meshes/body2.STL" />
      </geometry>
    </collision>
  </link>
  <joint
    name="jnt2"
    type="revolute">
    <origin
      xyz="0 0.2 0"
      rpy="3.1416 0 3.1416" />
    <parent
      link="body1" />
    <child
      link="body2" />
    <axis
      xyz="0 0 1" />
    <limit
      lower="-3.1416"
      upper="3.1416"
      effort="0"
      velocity="0" />
  </joint>
  <link
    name="body3">
    <inertial>
      <origin
        xyz="0.070782 3.024E-08 -5.5816E-08"
        rpy="0 0 0" />
      <mass
        value="0.26813" />
      <inertia
        ixx="6.19E-05"
        ixy="1.6236E-10"
        ixz="4.6572E-10"
        iyy="0.0012669"
        iyz="-2.9358E-10"
        izz="0.001262" />
    </inertial>
    <visual>
      <origin
        xyz="0 0 0"
        rpy="0 0 0" />
      <geometry>
        <mesh
          filename="package://Draw_armV4/meshes/body3.STL" />
      </geometry>
      <material
        name="">
        <color
          rgba="0.79216 0.81961 0.93333 1" />
      </material>
    </visual>
    <collision>
      <origin
        xyz="0 0 0"
        rpy="0 0 0" />
      <geometry>
        <mesh
          filename="package://Draw_armV4/meshes/body3.STL" />
      </geometry>
    </collision>
  </link>
  <joint
    name="jnt3"
    type="revolute">
    <origin
      xyz="0.2 0 0"
      rpy="0 0 0" />
    <parent
      link="body2" />
    <child
      link="body3" />
    <axis
      xyz="0 0 1" />
    <limit
      lower="-3.1416"
      upper="3.1416"
      effort="0"
      velocity="0" />
  </joint>
  <link
    name="body4">
    <inertial>
      <origin
        xyz="0.01209 -0.0044322 -5.6428E-10"
        rpy="0 0 0" />
      <mass
        value="0.13853" />
      <inertia
        ixx="4.8586E-05"
        ixy="1.3562E-11"
        ixz="1.9894E-11"
        iyy="6.6938E-05"
        iyz="-2.9259E-12"
        izz="7.0371E-05" />
    </inertial>
    <visual>
      <origin
        xyz="0 0 0"
        rpy="0 0 0" />
      <geometry>
        <mesh
          filename="package://Draw_armV4/meshes/body4.STL" />
      </geometry>
      <material
        name="">
        <color
          rgba="0.79216 0.81961 0.93333 1" />
      </material>
    </visual>
    <collision>
      <origin
        xyz="0 0 0"
        rpy="0 0 0" />
      <geometry>
        <mesh
          filename="package://Draw_armV4/meshes/body4.STL" />
      </geometry>
    </collision>
  </link>
  <joint
    name="jnt4"
    type="revolute">
    <origin
      xyz="0.2 0 0"
      rpy="0 0 0" />
    <parent
      link="body3" />
    <child
      link="body4" />
    <axis
      xyz="0 0 1" />
    <limit
      lower="-3.1416"
      upper="3.1416"
      effort="0"
      velocity="0" />
  </joint>
</robot>