<?xml version="1.0" encoding="utf-8"?>
<!-- This URDF was automatically created by SolidWorks to URDF Exporter! Originally created by Stephen Brawner (brawner@gmail.com) 
     Commit Version: 1.6.0-4-g7f85cfe  Build Version: 1.6.7995.38578
     For more information, please see http://wiki.ros.org/sw_urdf_exporter -->
<robot
  name="Draw_armV3">
  <link
    name="Plate">
    <inertial>
      <origin
        xyz="0 0.005 0"
        rpy="0 0 0" />
      <mass
        value="0.08" />
      <inertia
        ixx="0"
        ixy="0"
        ixz="0"
        iyy="0.00010933"
        iyz="0"
        izz="4.3333E-05" />
    </inertial>
    <visual>
      <origin
        xyz="0 0 0"
        rpy="0 0 0" />
      <geometry>
        <mesh
          filename="package://Draw_armV3/meshes/Plate.STL" />
      </geometry>
      <material
        name="">
        <color
          rgba="0.79216 0.81961 0.93333 1" />
      </material>
    </visual>
    <collision>
      <origin
        xyz="0 0 0"
        rpy="0 0 0" />
      <geometry>
        <mesh
          filename="package://Draw_armV3/meshes/Plate.STL" />
      </geometry>
    </collision>
  </link>
  <link
    name="body1">
    <inertial>
      <origin
        xyz="-0.026199 0.087562 -0.0024618"
        rpy="0 0 0" />
      <mass
        value="0.25155" />
      <inertia
        ixx="0.00095842"
        ixy="0.00037095"
        ixz="1.6629E-05"
        iyy="0.00021959"
        iyz="-3.152E-05"
        izz="0.0011096" />
    </inertial>
    <visual>
      <origin
        xyz="0 0 0"
        rpy="0 0 0" />
      <geometry>
        <mesh
          filename="package://Draw_armV3/meshes/body1.STL" />
      </geometry>
      <material
        name="">
        <color
          rgba="0.79216 0.81961 0.93333 1" />
      </material>
    </visual>
    <collision>
      <origin
        xyz="0 0 0"
        rpy="0 0 0" />
      <geometry>
        <mesh
          filename="package://Draw_armV3/meshes/body1.STL" />
      </geometry>
    </collision>
  </link>
  <joint
    name="jnt1"
    type="revolute">
    <origin
      xyz="0 0 0.01"
      rpy="1.5708 0 1.5708" />
    <parent
      link="Plate" />
    <child
      link="body1" />
    <axis
      xyz="0 1 0" />
    <limit
      lower="-3.14"
      upper="3.14"
      effort="0"
      velocity="0" />
  </joint>
  <link
    name="body2">
    <inertial>
      <origin
        xyz="0.05 0 0"
        rpy="0 0 0" />
      <mass
        value="0.22002" />
      <inertia
        ixx="5.4534E-05"
        ixy="0"
        ixz="0"
        iyy="0.00061648"
        iyz="0"
        izz="0.00061153" />
    </inertial>
    <visual>
      <origin
        xyz="0 0 0"
        rpy="0 0 0" />
      <geometry>
        <mesh
          filename="package://Draw_armV3/meshes/body2.STL" />
      </geometry>
      <material
        name="">
        <color
          rgba="0.79216 0.81961 0.93333 1" />
      </material>
    </visual>
    <collision>
      <origin
        xyz="0 0 0"
        rpy="0 0 0" />
      <geometry>
        <mesh
          filename="package://Draw_armV3/meshes/body2.STL" />
      </geometry>
    </collision>
  </link>
  <joint
    name="jnt2"
    type="revolute">
    <origin
      xyz="-0.075 0.2 0"
      rpy="0 0 0" />
    <parent
      link="body1" />
    <child
      link="body2" />
    <axis
      xyz="0 0 1" />
    <limit
      lower="-1.571"
      upper="1.571"
      effort="0"
      velocity="0" />
  </joint>
  <link
    name="body3">
    <inertial>
      <origin
        xyz="0.047995 2.3892E-08 -4.5465E-08"
        rpy="0 0 0" />
      <mass
        value="0.22002" />
      <inertia
        ixx="5.4534E-05"
        ixy="0"
        ixz="0"
        iyy="0.00061648"
        iyz="0"
        izz="0.00061153" />
    </inertial>
    <visual>
      <origin
        xyz="0 0 0"
        rpy="0 0 0" />
      <geometry>
        <mesh
          filename="package://Draw_armV3/meshes/body3.STL" />
      </geometry>
      <material
        name="">
        <color
          rgba="0.79216 0.81961 0.93333 1" />
      </material>
    </visual>
    <collision>
      <origin
        xyz="0 0 0"
        rpy="0 0 0" />
      <geometry>
        <mesh
          filename="package://Draw_armV3/meshes/body3.STL" />
      </geometry>
    </collision>
  </link>
  <joint
    name="jnt3"
    type="revolute">
    <origin
      xyz="0.15 0 0"
      rpy="0 0 0" />
    <parent
      link="body2" />
    <child
      link="body3" />
    <axis
      xyz="0 0 1" />
    <limit
      lower="-1.571"
      upper="1.571"
      effort="0"
      velocity="0" />
  </joint>
  <link
    name="body4">
    <inertial>
      <origin
        xyz="0.0075 0 0"
        rpy="0 0 0" />
      <mass
        value="0.12381" />
      <inertia
        ixx="3.9802E-05"
        ixy="0"
        ixz="0"
        iyy="0"
        iyz="0"
        izz="6.1587E-05" />
    </inertial>
    <visual>
      <origin
        xyz="0 0 0"
        rpy="0 0 0" />
      <geometry>
        <mesh
          filename="package://Draw_armV3/meshes/body4.STL" />
      </geometry>
      <material
        name="">
        <color
          rgba="0.79216 0.81961 0.93333 1" />
      </material>
    </visual>
    <collision>
      <origin
        xyz="0 0 0"
        rpy="0 0 0" />
      <geometry>
        <mesh
          filename="package://Draw_armV3/meshes/body4.STL" />
      </geometry>
    </collision>
  </link>
  <joint
    name="jnt4"
    type="revolute">
    <origin
      xyz="0.15 0 0"
      rpy="0 0 0" />
    <parent
      link="body3" />
    <child
      link="body4" />
    <axis
      xyz="0 0 1" />
    <limit
      lower="-1.571"
      upper="1.571"
      effort="0"
      velocity="0" />
  </joint>
  <link
    name="Pen">
    <inertial>
      <origin
        xyz="0 -0.041708 0"
        rpy="0 0 0" />
      <mass
        value="0.014722" />
      <inertia
        ixx="0"
        ixy="0"
        ixz="0"
        iyy="0"
        iyz="0"
        izz="0" />
    </inertial>
    <visual>
      <origin
        xyz="0 0 0"
        rpy="0 0 0" />
      <geometry>
        <mesh
          filename="package://Draw_armV3/meshes/Pen.STL" />
      </geometry>
      <material
        name="">
        <color
          rgba="0.79216 0.81961 0.93333 1" />
      </material>
    </visual>
    <collision>
      <origin
        xyz="0 0 0"
        rpy="0 0 0" />
      <geometry>
        <mesh
          filename="package://Draw_armV3/meshes/Pen.STL" />
      </geometry>
    </collision>
  </link>
  <joint
    name="pen"
    type="fixed">
    <origin
      xyz="0.05 0 0"
      rpy="0 0 0" />
    <parent
      link="body4" />
    <child
      link="Pen" />
    <axis
      xyz="0 0 0" />
    <limit
      lower="0"
      upper="0"
      effort="0"
      velocity="0" />
  </joint>
</robot>